# Generated by Django 5.0.6 on 2024-06-10 10:34

import django.contrib.auth.validators
from django.db import migrations, models


class Migration(migrations.Migration):

    dependencies = [
        ('users', '0018_alter_onetimecode_count_attempts'),
    ]

    operations = [
        migrations.AddField(
            model_name='customuser',
            name='username_en',
            field=models.CharField(error_messages={'unique': 'A user with that username already exists.'}, help_text='Required. 150 characters or fewer. Letters, digits and @/./+/-/_ only.', max_length=150, null=True, unique=True, validators=[django.contrib.auth.validators.UnicodeUsernameValidator()], verbose_name='username'),
        ),
        migrations.AddField(
            model_name='customuser',
            name='username_es',
            field=models.CharField(error_messages={'unique': 'A user with that username already exists.'}, help_text='Required. 150 characters or fewer. Letters, digits and @/./+/-/_ only.', max_length=150, null=True, unique=True, validators=[django.contrib.auth.validators.UnicodeUsernameValidator()], verbose_name='username'),
        ),
        migrations.AddField(
            model_name='customuser',
            name='username_ru',
            field=models.CharField(error_messages={'unique': 'A user with that username already exists.'}, help_text='Required. 150 characters or fewer. Letters, digits and @/./+/-/_ only.', max_length=150, null=True, unique=True, validators=[django.contrib.auth.validators.UnicodeUsernameValidator()], verbose_name='username'),
        ),
    ]
